<?xml version="1.0" encoding="UTF-8"?>
<robot generator="Robot 4.1.3 (Python 3.7.4 on win32)" generated="20230511 02:14:40.752" rpa="false" schemaversion="2">
<suite id="s1" name="Resource Py" source="C:\Users\suhelk\PycharmProjects\Automation\Automation\user defained keywords with Python\resource_py.robot">
<test id="s1-t1" name="fplder">
<kw name="folder_create">
<kw name="crete_folder">
<msg timestamp="20230511 02:14:41.150" level="FAIL">No keyword with name 'crete_folder' found.</msg>
<status status="FAIL" starttime="20230511 02:14:41.149" endtime="20230511 02:14:41.150"/>
</kw>
<status status="FAIL" starttime="20230511 02:14:41.145" endtime="20230511 02:14:41.151"/>
</kw>
<status status="FAIL" starttime="20230511 02:14:41.144" endtime="20230511 02:14:41.151">No keyword with name 'crete_folder' found.</status>
</test>
<status status="FAIL" starttime="20230511 02:14:40.755" endtime="20230511 02:14:41.153"/>
</suite>
<statistics>
<total>
<stat pass="0" fail="1" skip="0">All Tests</stat>
</total>
<tag>
</tag>
<suite>
<stat pass="0" fail="1" skip="0" id="s1" name="Resource Py">Resource Py</stat>
</suite>
</statistics>
<errors>
<msg timestamp="20230511 02:14:41.141" level="ERROR">Error in file 'C:\Users\suhelk\PycharmProjects\Automation\Automation\user defained keywords with Python\resource_py.robot' on line 3: Test library '..\Automation\user defained keywords with Python\create folder.py' does not exist.</msg>
</errors>
</robot>
